Workbook
Name 머릿글: TestCase!$B$1:$K$1

Sheet TestCase
A1: No | B1: 대분류 | C1: 중분류 | D1: 소분류 | E1: 테스트 시나리오 | F1: 테스트 조건 | G1: 실행 순서 | H1: Pass Result | I1: P/F | J1: 실제 결과 | K1: 비고 | L1: Tag
A2: =ROW()-2 -> 0 | B2: 게임실행 | C2: 실행 | D2: 게임실행 | E2: 클라이언트를 실행한다 | I2: N/T | K2: 유니티 프로젝트에서 테스트를 진행해 아직 클라이언트 실행을 진행하지 않음 | L2: =IF(B2="",L1,B2) -> 게임실행
A3: =ROW()-2 -> 1 | C3: 윈도우기능 | D3: 제목/아이콘 표시 | E3: 좁은창에서 제목표시줄 내용을 확인한다 | I3: N/T | L3: =IF(B3="",L2,B3) -> 게임실행
A4: =ROW()-2 -> 2 | E4: 넓은창에서 제목표시줄을 내용을 확인한다 | I4: N/T | L4: =IF(B4="",L3,B4) -> 게임실행
A5: =ROW()-2 -> 3 | D5: 최소화 | E5: 윈도우를 최소화 후 복귀한다 | I5: N/T | L5: =IF(B5="",L4,B5) -> 게임실행
A6: =ROW()-2 -> 4 | E6: 게임중 윈도우를 최소화 후 복귀한다 | I6: N/T | L6: =IF(B6="",L5,B6) -> 게임실행
A7: =ROW()-2 -> 5 | D7: 닫기 | E7: 윈도우를 닫는다 | I7: N/T | L7: =IF(B7="",L6,B7) -> 게임실행
A8: =ROW()-2 -> 6 | B8: 메뉴기능 | C8: 게임메뉴/UI | D8: Start | E8: 게임을 시작한다 | G8: 메인 메뉴에 있는 Start 버튼을 눌러 시작 | H8: "Home" 으로 화면 전환 | I8: Pass | L8: =IF(B8="",L7,B8) -> 메뉴기능
A9: =ROW()-2 -> 7 | D9: Setting | E9: 게임의 설정매뉴에 진행함 | G9: 메인 메뉴에 혹은 게임 도중 ESC키를 눌러 접근 | H9: 화면에 Setting UI 출력 | I9: Pass | L9: =IF(B9="",L8,B9) -> 메뉴기능
A10: =ROW()-2 -> 8 | D10: Setting-Music | E10: 게임의 음악볼륨을 조절한다 | G10: 1. 메인 메뉴 혹은 ESC를 눌러 Setting 메뉴 접근 2. Music(BGM)란에 있는 슬라이더를 이용해 조절 | H10: Float 값으로 음악볼륨이 조절됨 | I10: Pass | L10: =IF(B10="",L9,B10) -> 메뉴기능
A11: =ROW()-2 -> 9 | D11: Setting-Effect | E11: 게임의 효과볼륨을 조절한다 | G11: 1. 메인 메뉴 혹은 ESC를 눌러 Setting 메뉴 접근 2. Effect란에 있는 슬라이더를 이용해 조절 | H11: Float 값으로 효과음볼륨이 조절됨 | I11: Pass | L11: =IF(B11="",L10,B11) -> 메뉴기능
A12: =ROW()-2 -> 10 | D12: Setting-Key | E12: 조작법을 사용자 지정대로 변경 | G12: 1. 게임 플레이 도중 ESC를 눌러 Setting 메뉴 접근 2. Key 버튼을 눌러 Key Setting 매뉴 접근 3. 변경하고 싶은 조작란 칸을 클릭 4. 플레이어가 쓰고 싶은 키보드의 키를 입력 | H12: 인게임에서 플레이어가 지정한 키로 변경 | I12: Pass | L12: =IF(B12="",L11,B12) -> 메뉴기능
A13: =ROW()-2 -> 11 | D13: Exit | E13: 게임의 클라이언트를 종료 | G13: 1. 메인 메뉴에 있는 Exit 버튼을 눌러 선택창 접근 2. 'Yes' 혹은 'No' 버튼을 눌러 결정함 | H13: 선택에 따라 게임이 종료 됨 | I13: N/A | J13: 게임실행란 비고 참고 | L13: =IF(B13="",L12,B13) -> 메뉴기능
A14: =ROW()-2 -> 12 | D14: Home 내의 조력자 NPC | E14: 상호작용 가능여부 UI | G14: Home 씬에 있는 NPC 캐릭터에게 접근 | H14: 대화를 걸수 있을 상태일때 "Press [key] to talk"이 뜸 | I14: Pass | L14: =IF(B14="",L13,B14) -> 메뉴기능
A15: =ROW()-2 -> 13 | E15: 퀘스트 상호작용 UI 접근 | G15: 1. Home 씬에 있는 NPC 캐릭터에게 접근 2. 대화를 걸수 있을 상태일때 상호작용 키를 입력 | H15: 퀘스트 수락/거절 UI 출력 | I15: Pass | L15: =IF(B15="",L14,B15) -> 메뉴기능
A16: =ROW()-2 -> 14 | E16: 퀘스트 수락 혹은 거절 | G16: 1. 퀘스트 수락/거절 UI 매뉴 접근 2. Yes, No 버튼을 눌러 퀘스트 수락여부를 선택 | H16: Yes를 누를 시 스테이지 이동, No를 누를 시 UI 종료 | I16: Pass | L16: =IF(B16="",L15,B16) -> 메뉴기능
A17: =ROW()-2 -> 15 | D17: 미션 실패시 | E17: 퀘스트 실패 UI 출력 | G17: 적 NPC에게 제압을 당해 미션 수행이 불가해질시 | H17: 게임 오버 UI 출력 | I17: Pass | L17: =IF(B17="",L16,B17) -> 메뉴기능
A18: =ROW()-2 -> 16 | E18: 퀘스트 재시작 | G18: 게임오버 UI가 출력될 시 재시작 버튼을 선택 | H18: 게임을 Home에서 다시 시작 | I18: Pass | L18: =IF(B18="",L17,B18) -> 메뉴기능
A19: =ROW()-2 -> 17 | D19: 미션 성공시 | E19: 퀘스트 성공 UI 출력 | G19: 목표를 처리 해 미션 성공을 해야함 | H19: 미션 성공 UI 출력 | I19: Pass | L19: =IF(B19="",L18,B19) -> 메뉴기능
A20: =ROW()-2 -> 18 | E20: 홈 이동 | G20: 미션 성공 UI가 출력될 시 Home 버튼을 선택 | H20: 게임을 Home에서 다시 시작 | I20: Pass | L20: =IF(B20="",L19,B20) -> 메뉴기능
A21: =ROW()-2 -> 19 | D21: 무기 선택 UI | E21: 무기 선택 UI 출력 | G21: 1. Home에 있는 무기 상자에 접근 2. 상호작용 키를 입력 | H21: 무기 선택 UI가 출력 됨 | I21: Pass | L21: =IF(B21="",L20,B21) -> 메뉴기능
A22: =ROW()-2 -> 20 | E22: "Gun" 선택 | G22: "Gun" 버튼 선택 | H22: 해당 무기가 선택되며 UI 사라짐 | I22: Fail | J22: UI가 사라지지 않으며 ESC키로 Ui를 꺼야함 무기도 제대로 선택되지 않음 | L22: =IF(B22="",L21,B22) -> 메뉴기능
A23: =ROW()-2 -> 21 | E23: "CrowBar" 선택 | G23: "CrowBar" 버튼 선택 | H23: " | I23: Fail | L23: =IF(B23="",L22,B23) -> 메뉴기능
A24: =ROW()-2 -> 22 | E24: "Bat" 선택 | G24: "Bat" 버튼 선택 | H24: " | I24: Fail | L24: =IF(B24="",L23,B24) -> 메뉴기능
A25: =ROW()-2 -> 23 | D25: 무기 선택 필수 | E25: 무기를 골라야하는 요구 화면 출력 | F25: 무기를 미장착 | G25: 무기를 미장착한 상태에서 뭬스트 수락 버튼을 선택 | H25: "무기를 골라야합니다" 하는 텍스트가 출력이 됨 | I25: Pass | L25: =IF(B25="",L24,B25) -> 메뉴기능
A26: =ROW()-2 -> 24
A27: =ROW()-2 -> 25
A28: =ROW()-2 -> 26
A29: =ROW()-2 -> 27
A30: =ROW()-2 -> 28
A31: =ROW()-2 -> 29
A32: =ROW()-2 -> 30
A33: =ROW()-2 -> 31 | B33: 인게임기능 | C33: 게임 기능 | D33: 지뢰 카운터 | E33: 지뢰카운터 값을 감소시킨다 | G33: 1. 미확인블럭 우클릭 | H33: 지뢰카운터가 1 감소됨 | L33: =IF(B33="",L36,B33) -> 인게임기능
A34: =ROW()-2 -> 32 | E34: 지뢰카운터 값을 증가시킨다 | G34: 1. 깃발블럭 우클릭 | H34: 지뢰카운터가 1 증가됨 | L34: =IF(B34="",L33,B34) -> 인게임기능
A35: =ROW()-2 -> 33 | D35: 스마일버튼 | E35: 게임 시작전 스마일 버튼을 사용한다 | F35: 인게임 시작전 | G35: 1. 스마일버튼 클릭 | H35: 아무런 변화가 없다 | L35: =IF(B35="",L34,B35) -> 인게임기능
A36: =ROW()-2 -> 34 | E36: 게임 시작후 스마일 버튼을 사용한다 | F36: 인게임 시작후 | G36: 2. 스마일버튼 클릭 | H36: 게임이 초기화된다 | L36: =IF(B36="",L35,B36) -> 인게임기능
A37: =ROW()-2 -> 35 | D37: 초시계 | E37: 초시계 카운터를 시작한다 | G37: 1. 최초로 미확인 블럭 클릭 | H37: 1부터 초단위로 1씩 값이 증가한다 | L37: =IF(B37="",L36,B37) -> 인게임기능
A38: =ROW()-2 -> 36 | E38: 초시계 최대값을 확인한다 | G38: 1. 최초로 미확인 블럭 클릭 2. 999초 이상 대기 | H38: 1. 1부터 초단위로 1씩 값이 증가한다 2. 999초에서 증가가 멈춘다 | L38: =IF(B38="",L37,B38) -> 인게임기능
A39: =ROW()-2 -> 37 | C39: 게임 기능 | D39: 블럭 확인 | E39: 최로로 미확인 블럭을 클릭하여 확인한다 | F39: 최초 클릭 | G39: 1. 미확인 블럭 클릭 | H39: 다음중 하나로 변경됨 - 1~8 까지의 숫자 - 빈영역 | L39: =IF(B39="",L38,B39) -> 인게임기능 | Q39: Pass
A40: =ROW()-2 -> 38 | E40: 숫자블럭을 확인한다 | G40: 1. 미확인 블럭 클릭 2. 숫자블럭이 아니면 재실행 | H40: 1~8 까지의 숫자 블럭이 확인됨 | L40: =IF(B40="",L39,B40) -> 인게임기능 | P40: Pass: 테스트 성공 | Q40: N/T
...

Sheet TC MAP
A1: 테스트케이스 현황
A2: 분류 | B2: 개수 | C2: 비율 | D2: Pass | E2: Fail | F2: N/A | G2: Block | H2: N/T | I2: Total | J2: Total(%)
A3: 게임실행 | B3: =COUNTIF(TestCase!L:L,A3) -> 6 | C3: =IFERROR(B3/$B$6,0) -> 0.15 | D3: =_xlfn.COUNTIFS(TestCase!$I:$I,"*"&D$2&"*",TestCase!$L:$L,$A3) -> 0 | E3: =_xlfn.COUNTIFS(TestCase!$I:$I,"*"&E$2&"*",TestCase!$L:$L,$A3) -> 0 | F3: =_xlfn.COUNTIFS(TestCase!$I:$I,"*"&F$2&"*",TestCase!$L:$L,$A3) -> 0 | G3: =_xlfn.COUNTIFS(TestCase!$I:$I,"*"&G$2&"*",TestCase!$L:$L,$A3) -> 0 | H3: =_xlfn.COUNTIFS(TestCase!$I:$I,"*"&H$2&"*",TestCase!$L:$L,$A3) -> 6 | I3: =_xlfn.COUNTIFS(TestCase!$I:$I,"*"&I$2&"*",TestCase!$L:$L,$A3) -> 0 | J3: =I3/B3 -> 0
A4: 메뉴기능 | B4: =COUNTIF(TestCase!L:L,A4) -> 18 | C4: =IFERROR(B4/$B$6,0) -> 0.45 | D4: =_xlfn.COUNTIFS(TestCase!$I:$I,"*"&D$2&"*",TestCase!$L:$L,$A4) -> 14 | E4: =_xlfn.COUNTIFS(TestCase!$I:$I,"*"&E$2&"*",TestCase!$L:$L,$A4) -> 3 | F4: =_xlfn.COUNTIFS(TestCase!$I:$I,"*"&F$2&"*",TestCase!$L:$L,$A4) -> 1 | G4: =_xlfn.COUNTIFS(TestCase!$I:$I,"*"&G$2&"*",TestCase!$L:$L,$A4) -> 0 | H4: =_xlfn.COUNTIFS(TestCase!$I:$I,"*"&H$2&"*",TestCase!$L:$L,$A4) -> 0 | I4: =SUM(D4:H4) -> 18 | J4: =I4/B4 -> 1
A5: 인게임기능 | B5: =COUNTIF(TestCase!L:L,A5) -> 16 | C5: =IFERROR(B5/$B$6,0) -> 0.4 | D5: =_xlfn.COUNTIFS(TestCase!$I:$I,"*"&D$2&"*",TestCase!$L:$L,$A5) -> 0 | E5: =_xlfn.COUNTIFS(TestCase!$I:$I,"*"&E$2&"*",TestCase!$L:$L,$A5) -> 0 | F5: =_xlfn.COUNTIFS(TestCase!$I:$I,"*"&F$2&"*",TestCase!$L:$L,$A5) -> 0 | G5: =_xlfn.COUNTIFS(TestCase!$I:$I,"*"&G$2&"*",TestCase!$L:$L,$A5) -> 0 | H5: =_xlfn.COUNTIFS(TestCase!$I:$I,"*"&H$2&"*",TestCase!$L:$L,$A5) -> 0 | I5: =SUM(D5:H5) -> 0 | J5: =I5/B5 -> 0
A6: Total | B6: =SUM(B3:B5) -> 40 | C6: =SUM(C3:C5) -> 1 | D6: =SUM(D3:D5) -> 14 | E6: =SUM(E3:E5) -> 3 | F6: =SUM(F3:F5) -> 1 | G6: =SUM(G3:G5) -> 0 | H6: =SUM(H3:H5) -> 6 | I6: =SUM(I3:I5) -> 18
A7: Total(%) | D7: =D6/$B6 -> 0.35 | E7: =E6/$B6 -> 0.075 | F7: =F6/$B6 -> 0.025 | G7: =G6/$B6 -> 0 | H7: =H6/$B6 -> 0.15 | I7: =I6/$B6 -> 0.45
